Workbook

Sheet Capa
B2: Lista de Exercícios — Análise de Insumo-Produto
B5: Disciplina | C5: Análise de Insumo-Produto · PPGEco/UFES · 2026/1
B6: Professor | C6: Prof. Dr. Celso Bissoli Sessa
B7: Aluno | C7: Felipe Carvalho de Souza Santos
B8: Entrega | C8: 24/07/2026
B9: Dados | C9: Matrizes de Insumo-Produto do Brasil, 2010 e 2020 (Nível 68, NEREUS/CECEG; R$ milhões correntes)
B10: Ferramenta | C10: Arcabouço do repositório fcarva/es-insumo-produto (src/io_core.py; convenções de pesquisa/01, 17 e 25) — gerado por lista/resolver_lista.py
B12: Guia das abas
B13: Aba | C13: Conteúdo
B14: Metodologia | C14: Notas metodológicas e todas as premissas assumidas
B15: Setores | C15: Classificação setorial (Nível 68, comum a 2010 e 2020)
B16: Q1_Multiplicadores | C16: Multiplicadores de produção, emprego, renda e VA (tipos I e II) + rankings
B17: Q2_Choques | C17: Choques de R$ 10 bi: exportações da agricultura × FBCF
B18: Q3_UPCF | C18: Reajuste do salário mínimo (R$ 120 bi): importações e emprego
B19: Q4_RH | C19: Rasmussen-Hirschman 2010 × 2020 e setores-chave
B20: Q5_CampoInfluencia | C20: Campos de influência (Sonis-Hewings), Brasil 2010
B21: Q6_Extracao | C21: Extração hipotética total do setor escolhido (2020)
B22: Q7_SDA | C22: Decomposição estrutural 2010→2020 com atualização pelo IPCA
B23: Dados_2020 / Dados_2010 | C23: Vetores da MIP e coeficientes diretos (fórmulas)
B24: A, B, G, B2 | C24: Coeficientes técnicos, inversa de Leontief, inversa de Ghosh e modelo fechado (valores documentados — base das fórmulas)
B26: Legenda de células
B27: célula | C27: Amarelo-pastel, texto azul — entrada editável (choques, IPCA): a pasta recalcula
B28: célula | C28: Cinza-quente — parâmetros lidos da MIP (aba 12)
B29: célula | C29: Verde-pastel — linhas-síntese e totais
B30: célula | C30: Sem preenchimento — fórmula viva sobre as abas de dados/matrizes

Sheet Metodologia
B2: Notas metodológicas e premissas
B3: Todas as hipóteses assumidas na resolução estão listadas aqui; as fórmulas citadas seguem Miller & Blair (2009).
B5: 1. Modelo aberto: A = Z·x̂⁻¹ sobre os fluxos NACIONAIS (aba 12 da MIP-BR); B = (I−A)⁻¹ (Leontief); Ghosh: G = (I−x̂⁻¹Z)⁻¹. As matrizes B, G e B2 estão coladas como VALORES (inversão 68×68 feita externamente em NumPy — conferível por MINVERSE; a matriz A reproduz a aba 13 do arquivo-fonte com desvio < 1e-15); todas as demais células derivam delas por fórmula e recalculam.
B6: 2. Tipo II: modelo fechado para as famílias na CONVENÇÃO DA PLANILHA DO PROFESSOR (abas 20/22/23 da MIP) — a renda das famílias é o VALOR ADICIONADO BRUTO: linha adicional = VA por unidade de produção (v_va); coluna adicional = consumo das famílias por unidade da massa de VA. Reproduz a aba 23 (mult. tipo II) e a aba 22 (geradores tipo II) com desvio < 1e-14. O fechamento por remunerações (renda do trabalho apenas), usado no artigo do ES em pesquisa/17, é uma alternativa mais estreita.
B7: 3. Multiplicador de emprego em OCUPAÇÕES por R$ 1 milhão de demanda final; renda e VA em R$ por R$ de demanda final.
B8: 4. Q2: choque de R$ 10 bi = 10.000 (R$ milhões). Cenário (a): tudo na linha de exportações do setor Agricultura. Cenário (b): distribuído pela estrutura observada da coluna FBCF (produtos nacionais). Premissa: o choque recai sobre produtos nacionais nos dois cenários (célula de entrada editável).
B9: 5. Q3 (UPCF): o incremento de R$ 120 bi é repartido pela cesta observada do consumo das famílias a preço de CONSUMIDOR — nacional a preço básico + importados + impostos + margens (linhas Importação/Impostos/Margens × coluna Famílias da aba 12; a soma reproduz exatamente o consumo total). Margens são demanda por serviços de comércio e transporte e voltam ao vetor de choque nesses setores (rateio pelo VBP do grupo); impostos não geram produção; a parcela importada é importação DIRETA; a produção induzida gera importação INDUZIDA via m = importação intermediária/x. Emprego pelo modelo aberto (o choque JÁ é o consumo induzido).
B10: 6. Q4: índices de Rasmussen-Hirschman na convenção da aba 14 da MIP — AMBOS pela inversa de Leontief, normalizados pela média geral: para trás = soma de coluna de B (poder de dispersão); para frente = soma de linha de B (sensibilidade da dispersão); setor-chave: ambos > 1. Reproduz a aba 14 com desvio < 1e-14. A inversa de Ghosh (abas G_2010/G_2020) é uma medida alternativa de sensibilidade da oferta.
B11: 7. Q5: campo de influência (Sonis & Hewings) com ε = 0.001; S(i,j) = Σ dos quadrados de F = [B(ε)−B]/ε para perturbação unitária em a(i,j). Cálculo fechado por Sherman-Morrison — numericamente idêntico ao laço do material de apoio em R (Vale & Perobelli). Matriz S colada como valor; agregações por fórmula.
B12: 8. Q6: extração hipotética TOTAL (zera linha e coluna do setor em A e sua demanda final); perda medida contra o baseline modelado x = B·y.
B13: 9. Q7: SDA bipolar média (Dietzenbacher & Los): Δx = ½ΔB·(y0*+y1) + ½(B0+B1)·Δy, com y0* = y(2010)·fator IPCA. O deflator único (IPCA acumulado dez/2010→dez/2020, células editáveis na aba Q7) não altera A nem B de 2010 — coeficientes são razões —, agindo apenas sobre os níveis. Limitação declarada: o ideal seriam deflatores setoriais (duplo deflacionamento); o enunciado pede IPCA.
B14: 10. Unidades: R$ milhões correntes do ano de cada matriz (Q7 em preços de 2020).
... B19: Arquivo 2010: dados/MIP-BR 2010 (Nível 68).xlsm

Sheet Setores
B2: Classificação setorial
B3: Nível 68 (NEREUS/CECEG) — comum às matrizes de 2010 e 2020.
B6: Código | C6: Atividades | D6: nº
B7: 0191 | C7: Agricultura, inclusive o apoio à agricultura e a pós-colheita | D7: 1
B8: 0192 | C8: Pecuária, inclusive o apoio à pecuária | D8: 2
B9: 0280 | C9: Produção florestal; pesca e aquicultura | D9: 3
B10: 0580 | C10: Extração de carvão mineral e de minerais não-metálicos | D10: 4
B11: 0680 | C11: Extração de petróleo e gás, inclusive as atividades de apoio | D11: 5
B12: 0791 | C12: Extração de minério de ferro, inclusive beneficiamentos e a aglomeração | D12: 6
B13: 0792 | C13: Extração de minerais metálicos não-ferrosos, inclusive beneficiamentos | D13: 7
B14: 1091 | C14: Abate e produtos de carne, inclusive os produtos do laticínio e da pesca | D14: 8
B15: 1092 | C15: Fabricação e refino de açúcar | D15: 9
B16: 1093 | C16: Outros produtos alimentares | D16: 10
B17: 1100 | C17: Fabricação de bebidas | D17: 11
B18: 1200 | C18: Fabricação de produtos do fumo | D18: 12
... B74: 9700 | C74: Serviços domésticos | D74: 68

Sheet Dados_2020
B2: Dados — MIP Brasil 2020
B3: Valores correntes em R$ milhões; ocupações em pessoas. Vetores extraídos da aba 12 da MIP-BR (Nível 68), NEREUS/CECEG; coeficientes por unidade de produção calculados por fórmula nas colunas Q a T.
B6: Código | C6: Atividades | D6: nº | E6: VBP (x) | F6: Remunerações | G6: VA (PIB) | H6: Ocupações | I6: Importação intermediária | J6: Exportações | K6: Governo | L6: ISFLSF | M6: Consumo das famílias (nac.) | N6: FBCF | O6: Variação de estoques | P6: Demanda final total | Q6: w = ocup/x | R6: v renda = rem/x | S6: v VA = VA/x | T6: m = imp/x
B7: 0191 | C7: Agricultura, inclusive o apoio à agricultura e a pós-colheita | D7: 1 | E7: 549087 | F7: 32361 | G7: 303359 | H7: 6337753 | I7: 34265.178 | J7: 208838.11 | K7: 143.84694 | L7: 0 | M7: 99806.846 | N7: 3614.081 | O7: -3039.5917 | P7: =SUM(J7:O7) -> 309363.29 | Q7: =IF(E7=0,0,H7/E7) -> 11.542348 | R7: =IF(E7=0,0,F7/E7) -> 0.058936016 | S7: =IF(E7=0,0,G7/E7) -> 0.55247893 | T7: =IF(E7=0,0,I7/E7) -> 0.062403914
B8: 0192 | C8: Pecuária, inclusive o apoio à pecuária | D8: 2 | E8: 204149 | F8: 21595 | G8: 99993 | H8: 5525366 | I8: 7687.0251 | J8: 8459.0322 | K8: 8.9494976 | L8: 0 | M8: 34591.194 | N8: 20796.752 | O8: -886.61833 | P8: =SUM(J8:O8) -> 62969.309 | Q8: =IF(E8=0,0,H8/E8) -> 27.065359 | R8: =IF(E8=0,0,F8/E8) -> 0.10578058 | S8: =IF(E8=0,0,G8/E8) -> 0.48980402 | T8: =IF(E8=0,0,I8/E8) -> 0.037653994
B9: 0280 | C9: Produção florestal; pesca e aquicultura | D9: 3 | E9: 42525 | F9: 2470 | G9: 31269 | H9: 697280 | I9: 645.55509 | J9: 3465.3745 | K9: 4.1419293 | L9: 0 | M9: 20328.245 | N9: 1182.8698 | O9: -1148.6206 | P9: =SUM(J9:O9) -> 23832.01 | Q9: =IF(E9=0,0,H9/E9) -> 16.396943 | R9: =IF(E9=0,0,F9/E9) -> 0.05808348 | S9: =IF(E9=0,0,G9/E9) -> 0.73530864 | T9: =IF(E9=0,0,I9/E9) -> 0.015180602
B10: 0580 | C10: Extração de carvão mineral e de minerais não-metálicos | D10: 4 | E10: 23233 | F10: 4009 | G10: 9747 | H10: 104947 | I10: 1750.605 | J10: 1771.3915 | K10: 0.029836272 | L10: 0 | M10: 207.9483 | N10: 13.82895 | O10: 204.80208 | P10: =SUM(J10:O10) -> 2198.0007 | Q10: =IF(E10=0,0,H10/E10) -> 4.5171523 | R10: =IF(E10=0,0,F10/E10) -> 0.17255628 | S10: =IF(E10=0,0,G10/E10) -> 0.41953256 | T10: =IF(E10=0,0,I10/E10) -> 0.075349933
B11: 0680 | C11: Extração de petróleo e gás, inclusive as atividades de apoio | D11: 5 | E11: 238713 | F11: 19400 | G11: 90642 | H11: 51889 | I11: 30481.875 | J11: 90261.888 | K11: 0 | L11: 0 | M11: 636.09401 | N11: 35013.456 | O11: -17980.38 | P11: =SUM(J11:O11) -> 107931.06 | Q11: =IF(E11=0,0,H11/E11) -> 0.21736981 | R11: =IF(E11=0,0,F11/E11) -> 0.081269139 | S11: =IF(E11=0,0,G11/E11) -> 0.3797112 | T11: =IF(E11=0,0,I11/E11) -> 0.12769256
B12: 0791 | C12: Extração de minério de ferro, inclusive beneficiamentos e a aglomeração | D12: 6 | E12: 156454 | F12: 4870 | G12: 85756 | H12: 27455 | I12: 9552.8351 | J12: 119308.51 | K12: 0 | L12: 0 | M12: 37.09972 | N12: 1574.2415 | O12: -5378.3956 | P12: =SUM(J12:O12) -> 115541.46 | Q12: =IF(E12=0,0,H12/E12) -> 0.17548289 | R12: =IF(E12=0,0,F12/E12) -> 0.03112736 | S12: =IF(E12=0,0,G12/E12) -> 0.54812277 | T12: =IF(E12=0,0,I12/E12) -> 0.061058427
B13: 0792 | C13: Extração de minerais metálicos não-ferrosos, inclusive beneficiamentos | D13: 7 | E13: 23631 | F13: 2751 | G13: 7470 | H13: 27983 | I13: 2164.7747 | J13: 12255.885 | K13: 0 | L13: 0 | M13: 11.881807 | N13: 7.4426116 | O13: -1043.4319 | P13: =SUM(J13:O13) -> 11231.778 | Q13: =IF(E13=0,0,H13/E13) -> 1.1841649 | R13: =IF(E13=0,0,F13/E13) -> 0.11641488 | S13: =IF(E13=0,0,G13/E13) -> 0.31611019 | T13: =IF(E13=0,0,I13/E13) -> 0.09160741
B14: 1091 | C14: Abate e produtos de carne, inclusive os produtos do laticínio e da pesca | D14: 8 | E14: 398215 | F14: 34281 | G14: 58616 | H14: 818425 | I14: 8595.3699 | J14: 72631.118 | K14: 75.498021 | L14: 0 | M14: 245746.16 | N14: 224.92223 | O14: 1429.8181 | P14: =SUM(J14:O14) -> 320107.52 | Q14: =IF(E14=0,0,H14/E14) -> 2.055234 | R14: =IF(E14=0,0,F14/E14) -> 0.086086662 | S14: =IF(E14=0,0,G14/E14) -> 0.14719687 | T14: =IF(E14=0,0,I14/E14) -> 0.021584747
B15: 1092 | C15: Fabricação e refino de açúcar | D15: 9 | E15: 71299 | F15: 8261 | G15: 14749 | H15: 130365 | I15: 1332.2129 | J15: 32213.891 | K15: 0.10164997 | L15: 0 | M15: 16698.21 | N15: 208.07043 | O15: -1813.6346 | P15: =SUM(J15:O15) -> 47306.639 | Q15: =IF(E15=0,0,H15/E15) -> 1.8284268 | R15: =IF(E15=0,0,F15/E15) -> 0.11586418 | S15: =IF(E15=0,0,G15/E15) -> 0.20686125 | T15: =IF(E15=0,0,I15/E15) -> 0.018684876
B16: 1093 | C16: Outros produtos alimentares | D16: 10 | E16: 393619 | F16: 36586 | G16: 67425 | H16: 1223741 | I16: 18949.217 | J16: 43890.453 | K16: 73.366774 | L16: 0 | M16: 205118.62 | N16: 295.47642 | O16: 4940.4675 | P16: =SUM(J16:O16) -> 254318.39 | Q16: =IF(E16=0,0,H16/E16) -> 3.108948 | R16: =IF(E16=0,0,F16/E16) -> 0.092947749 | S16: =IF(E16=0,0,G16/E16) -> 0.17129508 | T16: =IF(E16=0,0,I16/E16) -> 0.048141011
B17: 1100 | C17: Fabricação de bebidas | D17: 11 | E17: 97251 | F17: 10044 | G17: 24280 | H17: 188466 | I17: 4539.1409 | J17: 2266.6768 | K17: 0.61871224 | L17: 0 | M17: 55191.928 | N17: 137.02848 | O17: 2849.024 | P17: =SUM(J17:O17) -> 60445.276 | Q17: =IF(E17=0,0,H17/E17) -> 1.9379338 | R17: =IF(E17=0,0,F17/E17) -> 0.10327914 | S17: =IF(E17=0,0,G17/E17) -> 0.24966324 | T17: =IF(E17=0,0,I17/E17) -> 0.046674491
B18: 1200 | C18: Fabricação de produtos do fumo | D18: 12 | E18: 17271 | F18: 1839 | G18: 3834 | H18: 16862 | I18: 881.86997 | J18: 2908.666 | K18: 0 | L18: 0 | M18: 13566.817 | N18: 105.93811 | O18: -78.811753 | P18: =SUM(J18:O18) -> 16502.61 | Q18: =IF(E18=0,0,H18/E18) -> 0.97631868 | R18: =IF(E18=0,0,F18/E18) -> 0.10647907 | S18: =IF(E18=0,0,G18/E18) -> 0.22199062 | T18: =IF(E18=0,0,I18/E18) -> 0.051060736
... B74: 9700 | C74: Serviços domésticos | D74: 68 | E74: 59474 | F74: 59474 | G74: 59474 | H74: 5518847 | I74: 0 | J74: 0 | K74: 0 | L74: 0 | M74: 59474 | N74: 0 | O74: 0 | P74: =SUM(J74:O74) -> 59474 | Q74: =IF(E74=0,0,H74/E74) -> 92.79428 | R74: =IF(E74=0,0,F74/E74) -> 1 | S74: =IF(E74=0,0,G74/E74) -> 1 | T74: =IF(E74=0,0,I74/E74) -> 0
C75: TOTAL | E75: =SUM(E7:E74) -> 13306199 | F75: =SUM(F7:F74) -> 3192343 | G75: =SUM(G7:G74) -> 6594937 | H75: =SUM(H7:H74) -> 99254676 | I75: =SUM(I7:I74) -> 723062.02 | J75: =SUM(J7:J74) -> 1061746.5 | K75: =SUM(K7:K74) -> 1524987.7 | L75: =SUM(L7:L74) -> 101399.63 | ... P75: =SUM(P7:P74) -> 7161994.7

Sheet Dados_2010
B2: Dados — MIP Brasil 2010
B3: Valores correntes em R$ milhões; ocupações em pessoas. Vetores extraídos da aba 12 da MIP-BR (Nível 68), NEREUS/CECEG; coeficientes por unidade de produção calculados por fórmula nas colunas Q a T.
B6: Código | C6: Atividades | D6: nº | E6: VBP (x) | F6: Remunerações | G6: VA (PIB) | H6: Ocupações | I6: Importação intermediária | J6: Exportações | K6: Governo | L6: ISFLSF | M6: Consumo das famílias (nac.) | N6: FBCF | O6: Variação de estoques | P6: Demanda final total | Q6: w = ocup/x | R6: v renda = rem/x | S6: v VA = VA/x | T6: m = imp/x
B7: 0191 | C7: Agricultura, inclusive o apoio à agricultura e a pós-colheita | D7: 1 | E7: 168861 | F7: 21587 | G7: 100111 | H7: 6965949 | I7: 5556.3335 | J7: 31349.798 | K7: 162.53816 | L7: 0 | M7: 38738.809 | N7: 1972.731 | O7: 384.79463 | P7: =SUM(J7:O7) -> 72608.671 | Q7: =IF(E7=0,0,H7/E7) -> 41.252563 | R7: =IF(E7=0,0,F7/E7) -> 0.12783887 | S7: =IF(E7=0,0,G7/E7) -> 0.5928604 | T7: =IF(E7=0,0,I7/E7) -> 0.032904777
B8: 0192 | C8: Pecuária, inclusive o apoio à pecuária | D8: 2 | E8: 83448 | F8: 14062 | G8: 44863 | H8: 7473681 | I8: 1980.0532 | J8: 2712.8882 | K8: 10.515784 | L8: 0 | M8: 13254.171 | N8: 10470.544 | O8: 1034.3665 | P8: =SUM(J8:O8) -> 27482.485 | Q8: =IF(E8=0,0,H8/E8) -> 89.560936 | R8: =IF(E8=0,0,F8/E8) -> 0.16851213 | S8: =IF(E8=0,0,G8/E8) -> 0.53761624 | T8: =IF(E8=0,0,I8/E8) -> 0.023727989
B9: 0280 | C9: Produção florestal; pesca e aquicultura | D9: 3 | E9: 20332 | F9: 1983 | G9: 14958 | H9: 1041304 | I9: 299.92137 | J9: 457.17801 | K9: 2.5459381 | L9: 0 | M9: 7475.6452 | N9: 1252.48 | O9: -118.33432 | P9: =SUM(J9:O9) -> 9069.5148 | Q9: =IF(E9=0,0,H9/E9) -> 51.21503 | R9: =IF(E9=0,0,F9/E9) -> 0.097530986 | S9: =IF(E9=0,0,G9/E9) -> 0.73568759 | T9: =IF(E9=0,0,I9/E9) -> 0.014751199
B10: 0580 | C10: Extração de carvão mineral e de minerais não-metálicos | D10: 4 | E10: 14838 | F10: 2772 | G10: 6592 | H10: 138960 | I10: 768.64363 | J10: 593.77909 | K10: 0.089084302 | L10: 0 | M10: 465.81338 | N10: 35.818985 | O10: -306.27138 | P10: =SUM(J10:O10) -> 789.22915 | Q10: =IF(E10=0,0,H10/E10) -> 9.3651436 | R10: =IF(E10=0,0,F10/E10) -> 0.18681763 | S10: =IF(E10=0,0,G10/E10) -> 0.44426473 | T10: =IF(E10=0,0,I10/E10) -> 0.051802374
B11: 0680 | C11: Extração de petróleo e gás, inclusive as atividades de apoio | D11: 5 | E11: 117330 | F11: 12201 | G11: 63474 | H11: 60278 | I11: 8185.7564 | J11: 23128.241 | K11: 0 | L11: 0 | M11: 285.48345 | N11: 12022.338 | O11: -455.91922 | P11: =SUM(J11:O11) -> 34980.142 | Q11: =IF(E11=0,0,H11/E11) -> 0.51374755 | R11: =IF(E11=0,0,F11/E11) -> 0.10398875 | S11: =IF(E11=0,0,G11/E11) -> 0.54098696 | T11: =IF(E11=0,0,I11/E11) -> 0.069766951
B12: 0791 | C12: Extração de minério de ferro, inclusive beneficiamentos e a aglomeração | D12: 6 | E12: 56525 | F12: 3687 | G12: 36491 | H12: 35928 | I12: 1964.8914 | J12: 44613.201 | K12: 0 | L12: 0 | M12: 5.7744916 | N12: 187.08454 | O12: -216.70866 | P12: =SUM(J12:O12) -> 44589.351 | Q12: =IF(E12=0,0,H12/E12) -> 0.63561256 | R12: =IF(E12=0,0,F12/E12) -> 0.065227775 | S12: =IF(E12=0,0,G12/E12) -> 0.64557276 | T12: =IF(E12=0,0,I12/E12) -> 0.034761458
B13: 0792 | C13: Extração de minerais metálicos não-ferrosos, inclusive beneficiamentos | D13: 7 | E13: 9864 | F13: 1507 | G13: 3408 | H13: 31775 | I13: 659.06501 | J13: 2232.2045 | K13: 0 | L13: 0 | M13: 3.930707 | N13: 0 | O13: 360.15829 | P13: =SUM(J13:O13) -> 2596.2935 | Q13: =IF(E13=0,0,H13/E13) -> 3.2213098 | R13: =IF(E13=0,0,F13/E13) -> 0.15277778 | S13: =IF(E13=0,0,G13/E13) -> 0.34549878 | T13: =IF(E13=0,0,I13/E13) -> 0.066815187
B14: 1091 | C14: Abate e produtos de carne, inclusive os produtos do laticínio e da pesca | D14: 8 | E14: 137527 | F14: 13111 | G14: 20849 | H14: 638392 | I14: 1944.2879 | J14: 18341.431 | K14: 35.819844 | L14: 0 | M14: 91316.525 | N14: 45.574045 | O14: 1496.6954 | P14: =SUM(J14:O14) -> 111236.05 | Q14: =IF(E14=0,0,H14/E14) -> 4.6419394 | R14: =IF(E14=0,0,F14/E14) -> 0.095334007 | S14: =IF(E14=0,0,G14/E14) -> 0.15159932 | T14: =IF(E14=0,0,I14/E14) -> 0.0141375
B15: 1092 | C15: Fabricação e refino de açúcar | D15: 9 | E15: 44422 | F15: 6175 | G15: 9545 | H15: 228655 | I15: 565.65449 | J15: 16579.453 | K15: 2.2025413 | L15: 0 | M15: 13243.258 | N15: 224.56534 | O15: 725.7809 | P15: =SUM(J15:O15) -> 30775.26 | Q15: =IF(E15=0,0,H15/E15) -> 5.1473369 | R15: =IF(E15=0,0,F15/E15) -> 0.1390077 | S15: =IF(E15=0,0,G15/E15) -> 0.21487101 | T15: =IF(E15=0,0,I15/E15) -> 0.012733657
B16: 1093 | C16: Outros produtos alimentares | D16: 10 | E16: 153990 | F16: 16095 | G16: 27485 | H16: 1115497 | I16: 6123.3806 | J16: 13882.687 | K16: 33.26736 | L16: 0 | M16: 88499.476 | N16: 264.68219 | O16: 2828.4347 | P16: =SUM(J16:O16) -> 105508.55 | Q16: =IF(E16=0,0,H16/E16) -> 7.2439574 | R16: =IF(E16=0,0,F16/E16) -> 0.10451977 | S16: =IF(E16=0,0,G16/E16) -> 0.17848562 | T16: =IF(E16=0,0,I16/E16) -> 0.039764794
B17: 1100 | C17: Fabricação de bebidas | D17: 11 | E17: 53034 | F17: 5267 | G17: 17224 | H17: 161508 | I17: 1575.4188 | J17: 969.91061 | K17: 1.7504317 | L17: 0 | M17: 30131.334 | N17: 150.36957 | O17: 634.4348 | P17: =SUM(J17:O17) -> 31887.799 | Q17: =IF(E17=0,0,H17/E17) -> 3.0453671 | R17: =IF(E17=0,0,F17/E17) -> 0.099313648 | S17: =IF(E17=0,0,G17/E17) -> 0.32477279 | T17: =IF(E17=0,0,I17/E17) -> 0.029705826
B18: 1200 | C18: Fabricação de produtos do fumo | D18: 12 | E18: 13405 | F18: 1148 | G18: 3595 | H18: 19343 | I18: 538.84466 | J18: 2508.8771 | K18: 0 | L18: 0 | M18: 9906.8051 | N18: 39.48518 | O18: -56.785708 | P18: =SUM(J18:O18) -> 12398.382 | Q18: =IF(E18=0,0,H18/E18) -> 1.442969 | R18: =IF(E18=0,0,F18/E18) -> 0.085639687 | S18: =IF(E18=0,0,G18/E18) -> 0.26818351 | T18: =IF(E18=0,0,I18/E18) -> 0.040197289
... B74: 9700 | C74: Serviços domésticos | D74: 68 | E74: 40334 | F74: 40334 | G74: 40334 | H74: 6780014 | I74: 0 | J74: 0 | K74: 0 | L74: 0 | M74: 40334 | N74: 0 | O74: 0 | P74: =SUM(J74:O74) -> 40334 | Q74: =IF(E74=0,0,H74/E74) -> 168.09674 | R74: =IF(E74=0,0,F74/E74) -> 1 | S74: =IF(E74=0,0,G74/E74) -> 1 | T74: =IF(E74=0,0,I74/E74) -> 0
C75: TOTAL | E75: =SUM(E7:E74) -> 6599149 | F75: =SUM(F7:F74) -> 1618190 | G75: =SUM(G7:G74) -> 3302840 | H75: =SUM(H7:H74) -> 98116218 | I75: =SUM(I7:I74) -> 274871.08 | J75: =SUM(J7:J74) -> 352943.89 | K75: =SUM(K7:K74) -> 733881.93 | L75: =SUM(L7:L74) -> 59667.456 | ... P75: =SUM(P7:P74) -> 3568197.1

Sheet A_2020
B2: Matriz A — coeficientes técnicos nacionais (2020)
B3: a(i,j) = Z(i,j)/x(j); reproduz a aba 13 do arquivo-fonte (desvio < 1e-15).
B6: Código | C6: Atividades | E6: 1 | F6: 2 | G6: 3 | H6: 4 | I6: 5 | J6: 6 | K6: 7 | L6: 8 | M6: 9 | N6: 10 | O6: 11 | P6: 12 | Q6: 13 | R6: 14 | S6: 15 | T6: 16 | U6: 17 | V6: 18 | W6: 19 | X6: 20 | Y6: 21 | Z6: 22 | AA6: 23 | AB6: 24 | AC6: 25 | AD6: 26 | AE6: 27 | AF6: 28 | AG6: 29 | AH6: 30 | AI6: 31 | AJ6: 32 | AK6: 33 | AL6: 34 | AM6: 35 | AN6: 36 | AO6: 37 | AP6: 38 | AQ6: 39 | AR6: 40 | AS6: 41 | AT6: 42 | AU6: 43 | AV6: 44 | AW6: 45 | AX6: 46 | AY6: 47 | AZ6: 48 | BA6: 49 | BB6: 50 | BC6: 51 | BD6: 52 | BE6: 53 | BF6: 54 | BG6: 55 | BH6: 56 | BI6: 57 | BJ6: 58 | BK6: 59 | BL6: 60 | BM6: 61 | BN6: 62 | BO6: 63 | BP6: 64 | BQ6: 65 | BR6: 66 | BS6: 67 | BT6: 68
B7: 0191 | C7: Agricultura, inclusive o apoio à agricultura e a pós-colheita | D7: 1 | E7: 0.021716404 | F7: 0.042666048 | G7: 0.0045552159 | H7: 7.1846084e-05 | I7: 3.7636312e-05 | J7: 8.8366484e-05 | K7: 0.00011683352 | L7: 0.025890695 | M7: 0.46812247 | N7: 0.27620531 | O7: 0.030180497 | P7: 0.2785277 | Q7: 0.12431647 | R7: 0.011885214 | S7: 0.00016757449 | T7: 0.002279003 | U7: 0.0016318554 | V7: 1.1546433e-05 | W7: 2.3165475e-05 | X7: 0.37813778 | Y7: 8.8851249e-05 | Z7: 0.00015079689 | AA7: 4.1695044e-05 | AB7: 0.00022608255 | AC7: 0.00024727771 | AD7: 0.00016221647 | AE7: 0.00027528654 | AF7: 0.0003581842 | AG7: 3.1071834e-05 | AH7: 2.1327893e-06 | AI7: 3.0984664e-06 | AJ7: 5.1031497e-06 | AK7: 3.0017581e-06 | AL7: 3.4014765e-06 | AM7: 1.1562853e-05 | AN7: 0.00015348694 | AO7: 6.191892e-07 | AP7: 1.3871582e-06 | AQ7: 0.00047540239 | AR7: 0.00069794348 | AS7: 1.5421603e-05 | AT7: 0.01189369 | AU7: 2.5553073e-06 | AV7: 1.6103305e-06 | AW7: 6.5902006e-06 | AX7: 9.2573236e-05 | AY7: 0.012027636 | AZ7: 0.019245253 | BA7: 5.0271801e-06 | BB7: 1.3301733e-05 | BC7: 0.00023436517 | BD7: 1.2975865e-05 | BE7: 2.0299995e-05 | BF7: 2.9840003e-05 | BG7: 3.5749744e-05 | BH7: 0.00018406429 | BI7: 8.6242898e-06 | BJ7: 1.3416509e-05 | BK7: 0.00055741825 | BL7: 5.9768536e-06 | BM7: 0.0011680788 | BN7: 0.0010269768 | BO7: 0.00046819122 | BP7: 0.0020736436 | BQ7: 0.00064829248 | BR7: 7.5968112e-05 | BS7: 0.0019645627 | BT7: 0
B8: 0192 | C8: Pecuária, inclusive o apoio à pecuária | D8: 2 | E8: 0.0026517889 | F8: 0.043924466 | G8: 0.0059273028 | H8: 0.00016511796 | I8: 8.7857976e-05 | J8: 0.00015404297 | K8: 0.00020587229 | L8: 0.29513066 | M8: 0.0025505128 | N8: 0.01531257 | O8: 0.00083791281 | P8: 0.011801096 | Q8: 0.0067616618 | R8: 0.0047026335 | S8: 0.00015357649 | T8: 0.0043306958 | U8: 0.0027491695 | V8: 2.0020176e-05 | W8: 1.8355937e-06 | X8: 0.0033243315 | Y8: 0.00029496044 | Z8: 6.8681439e-05 | AA8: 9.9306981e-05 | AB8: 9.3589536e-05 | AC8: 0.00039124623 | AD8: 0.00070750645 | AE8: 0.00055086639 | AF8: 0.00065513915 | AG8: 2.5887911e-05 | AH8: 4.8088528e-06 | AI8: 9.8214091e-06 | AJ8: 1.0394753e-05 | AK8: 5.6524653e-06 | AL8: 8.000317e-06 | AM8: 1.7635354e-05 | AN8: 9.3253724e-05 | AO8: 1.7539227e-06 | AP8: 2.1412793e-06 | AQ8: 7.9154276e-05 | AR8: 0.0013038434 | AS8: 1.8202671e-05 | AT8: 0.00034303258 | AU8: 2.3796621e-06 | AV8: 1.8124664e-06 | AW8: 6.6712651e-06 | AX8: 0.00015769004 | AY8: 0.014225233 | AZ8: 0.0085150241 | BA8: 9.3507018e-06 | BB8: 2.2867286e-05 | BC8: 0.00040818755 | BD8: 2.3370185e-05 | BE8: 3.3189614e-05 | BF8: 5.4937531e-05 | BG8: 2.9751018e-05 | BH8: 0.00022280744 | BI8: 7.0918548e-05 | BJ8: 1.8907603e-05 | BK8: 0.00012171706 | BL8: 8.2264673e-06 | BM8: 0.00038341884 | BN8: 0.00034609117 | BO8: 0.00016861049 | BP8: 0.00062664671 | BQ8: 0.00032563404 | BR8: 8.0549455e-05 | BS8: 0.00026727641 | BT8: 0
B9: 0280 | C9: Produção florestal; pesca e aquicultura | D9: 3 | E9: 0.0032342991 | F9: 0.008539683 | G9: 0.05841453 | H9: 7.7652587e-05 | I9: 6.7404855e-06 | J9: 1.1163426e-05 | K9: 1.4680667e-05 | L9: 0.0065225064 | M9: 9.1731872e-06 | N9: 0.00079975602 | O9: 0.00016095405 | P9: 0.0007300534 | Q9: 0.0005900436 | R9: 0.00015330969 | S9: 0.00015094432 | T9: 0.051892405 | U9: 0.032259109 | V9: 1.527558e-06 | W9: 1.5015903e-07 | X9: 6.8392122e-05 | Y9: 0.0011104097 | Z9: 2.3890094e-05 | AA9: 1.4503091e-06 | AB9: 1.8433686e-06 | AC9: 0.004465193 | AD9: 0.00078334434 | AE9: 0.006181333 | AF9: 4.6940691e-05 | AG9: 5.6056106e-05 | AH9: 4.8442493e-07 | AI9: 9.04961e-07 | AJ9: 1.1227704e-06 | AK9: 5.565342e-07 | AL9: 7.8149627e-07 | AM9: 1.4629875e-06 | AN9: 3.4603681e-05 | AO9: 2.0472105e-07 | AP9: 3.5864194e-07 | AQ9: 5.6308698e-06 | AR9: 0.0013042173 | AS9: 1.9278386e-06 | AT9: 0.00016894888 | AU9: 3.0875136e-07 | AV9: 2.4284569e-07 | AW9: 5.6215158e-07 | AX9: 1.1947762e-05 | AY9: 0.0014922131 | AZ9: 0.002040406 | BA9: 1.1978847e-06 | BB9: 2.3944198e-06 | BC9: 2.9316507e-05 | BD9: 2.1835791e-06 | BE9: 2.6144106e-06 | BF9: 4.1048843e-06 | BG9: 2.8327544e-06 | BH9: 5.3918899e-05 | BI9: 1.0676524e-06 | BJ9: 2.0639463e-06 | BK9: 8.4945108e-06 | BL9: 8.6073155e-07 | BM9: 0.00011991758 | BN9: 0.00019805992 | BO9: 7.5899535e-05 | BP9: 0.00038265428 | BQ9: 5.4535912e-05 | BR9: 8.4571076e-06 | BS9: 1.7326071e-05 | BT9: 0
B10: 0580 | C10: Extração de carvão mineral e de minerais não-metálicos | D10: 4 | E10: 0.00029086183 | F10: 0.0024691239 | G10: 0.00034778484 | H10: 0.011913425 | I10: 0.0028747825 | J10: 6.2585455e-06 | K10: 0.00034513864 | L10: 0.00017949367 | M10: 0.00015398242 | N10: 0.00076075716 | O10: 0.00021787858 | P10: 8.4868187e-06 | Q10: 1.7040905e-05 | R10: 1.0339947e-05 | S10: 2.1119754e-05 | T10: 7.1133004e-06 | U10: 0.0001175198 | V10: 1.8469204e-05 | W10: 1.4979592e-05 | X10: 0.0026941647 | Y10: 0.017288895 | Z10: 0.00073244339 | AA10: 0.00010981474 | AB10: 2.4114014e-05 | AC10: 4.8413447e-05 | AD10: 0.053912593 | AE10: 0.009435352 | AF10: 0.0048117851 | AG10: 6.2237438e-05 | AH10: 6.7361461e-06 | AI10: 0.00053303912 | AJ10: 4.8122893e-05 | AK10: 0.00010293603 | AL10: 0.00034634055 | AM10: 5.6060458e-05 | AN10: 0.00037454829 | AO10: 4.3463248e-05 | AP10: 0.00059243303 | AQ10: 0.0047901992 | AR10: 0.010132676 | AS10: 2.4452797e-05 | AT10: 8.7319236e-05 | AU10: 2.1695768e-06 | AV10: 3.119142e-06 | AW10: 1.7655844e-06 | AX10: 3.9124347e-05 | AY10: 9.6307522e-05 | AZ10: 5.2558834e-05 | BA10: 1.6870646e-05 | BB10: 1.3622628e-05 | BC10: 1.6001734e-05 | BD10: 8.6260455e-06 | BE10: 4.842772e-06 | BF10: 0.00049875543 | BG10: 1.5736778e-05 | BH10: 2.5739559e-05 | BI10: 8.2856462e-06 | BJ10: 1.2740585e-05 | BK10: 1.2671905e-05 | BL10: 5.0488828e-06 | BM10: 8.3478908e-05 | BN10: 4.6095243e-05 | BO10: 2.5311686e-05 | BP10: 4.6695328e-05 | BQ10: 1.4809083e-05 | BR10: 6.1032838e-05 | BS10: 2.6773111e-05 | BT10: 0
B11: 0680 | C11: Extração de petróleo e gás, inclusive as atividades de apoio | D11: 5 | E11: 4.6337279e-05 | F11: 8.2878207e-05 | G11: 2.2827539e-05 | H11: 0.00013030638 | I11: 0.029883749 | J11: 0.0050617839 | K11: 0.0027417904 | L11: 0.0001250213 | M11: 7.3804608e-06 | N11: 0.0011743502 | O11: 0.00089422503 | P11: 8.9975296e-06 | Q11: 0.0011785302 | R11: 1.5717731e-05 | S11: 3.1915478e-05 | T11: 0.00080367052 | U11: 0.0035681681 | V11: 6.4634479e-06 | W11: 0.23394728 | X11: 6.5123529e-06 | Y11: 0.0053042223 | Z11: 0.00049673019 | AA11: 0.00031277567 | AB11: 0.00025057124 | AC11: 0.00043633189 | AD11: 0.0035041154 | AE11: 0.0014986019 | AF11: 0.0022485303 | AG11: 0.001742177 | AH11: 4.4761673e-06 | AI11: 0.00021777373 | AJ11: 8.4157847e-05 | AK11: 0.00018677814 | AL11: 0.00076132768 | AM11: 7.9635343e-06 | AN11: 1.7867295e-05 | AO11: 3.6114401e-05 | AP11: 0.025672189 | AQ11: 0.013231583 | AR11: 0.0022016498 | AS11: 5.2001975e-05 | AT11: 0.00013327693 | AU11: 0.00027221488 | AV11: 3.9373774e-05 | AW11: 6.8546218e-06 | AX11: 0.00064583993 | AY11: 0.00011233301 | AZ11: 0.00016344766 | BA11: 2.5110283e-05 | BB11: 2.9170729e-05 | BC11: 0.00089145709 | BD11: 2.8632258e-05 | BE11: 1.8620485e-05 | BF11: 7.9338412e-06 | BG11: 5.726936e-05 | BH11: 0.00090192013 | BI11: 3.0478478e-05 | BJ11: 9.6897747e-05 | BK11: 3.2231068e-05 | BL11: 1.7031789e-05 | BM11: 0.0026972984 | BN11: 6.4451933e-05 | BO11: 9.4898863e-05 | BP11: 6.9070784e-06 | BQ11: 2.2467326e-05 | BR11: 0.0002358578 | BS11: 0.00020074591 | BT11: 0
B12: 0791 | C12: Extração de minério de ferro, inclusive beneficiamentos e a aglomeração | D12: 6 | E12: 1.1437166e-06 | F12: 6.2244961e-06 | G12: 2.371864e-06 | H12: 1.5537172e-05 | I12: 0.0002370286 | J12: 0.024516073 | K12: 0.0041847665 | L12: 2.0333408e-06 | M12: 7.7718662e-07 | N12: 2.3684825e-06 | O12: 2.5143723e-06 | P12: 3.0789204e-06 | Q12: 2.8423699e-06 | R12: 7.2237545e-07 | S12: 1.2803549e-06 | T12: 1.9421555e-05 | U12: 4.5878335e-06 | V12: 2.1410183e-05 | W12: 4.3264916e-07 | X12: 7.4004011e-08 | Y12: 1.3933087e-06 | Z12: 3.0784572e-06 | AA12: 2.8190768e-06 | AB12: 7.2459332e-06 | AC12: 5.9929882e-06 | AD12: 0.0024070866 | AE12: 0.23271843 | AF12: 0.0012278784 | AG12: 3.5414741e-05 | AH12: 6.5376637e-06 | AI12: 0.00013852335 | AJ12: 0.00086451737 | AK12: 5.8618327e-05 | AL12: 4.1804916e-05 | AM12: 9.5940529e-05 | AN12: 3.452824e-05 | AO12: 0.00080621449 | AP12: 1.0395187e-06 | AQ12: 0.00023189965 | AR12: 0.00032917043 | AS12: 1.3261949e-05 | AT12: 4.6890289e-06 | AU12: 3.4998926e-06 | AV12: 5.5261814e-05 | AW12: 7.7893429e-08 | AX12: 6.0573087e-05 | AY12: 1.1577791e-05 | AZ12: 1.1332408e-05 | BA12: 5.8691608e-07 | BB12: 3.202353e-07 | BC12: 0.00012364324 | BD12: 1.8692796e-06 | BE12: 7.3982004e-06 | BF12: 1.2130537e-05 | BG12: 6.3000169e-06 | BH12: 0.00015228235 | BI12: 7.1816466e-07 | BJ12: 1.985298e-06 | BK12: 6.3643746e-05 | BL12: 1.459038e-06 | BM12: 5.9691024e-05 | BN12: 5.9116415e-06 | BO12: 1.0961119e-06 | BP12: 6.5897275e-05 | BQ12: 3.0209657e-07 | BR12: 1.7561109e-05 | BS12: 3.1306924e-06 | BT12: 0
B13: 0792 | C13: Extração de minerais metálicos não-ferrosos, inclusive beneficiamentos | D13: 7 | E13: 8.2611066e-06 | F13: 1.2354555e-05 | G13: 1.9655612e-06 | H13: 6.9420942e-06 | I13: 0.00032562436 | J13: 0.00011663137 | K13: 0.068188001 | L13: 2.3048991e-05 | M13: 2.4848571e-06 | N13: 4.1766491e-05 | O13: 2.3109577e-05 | P13: 2.1113233e-07 | Q13: 4.2695793e-07 | R13: 3.8003621e-08 | S13: 6.0262805e-07 | T13: 5.7300072e-08 | U13: 5.9721489e-05 | V13: 0.00029467803 | W13: 0 | X13: 1.0499426e-06 | Y13: 3.1527027e-05 | Z13: 4.8554118e-05 | AA13: 9.655364e-06 | AB13: 4.3433658e-06 | AC13: 1.8110123e-05 | AD13: 0.00060468634 | AE13: 0.011375087 | AF13: 0.096345806 | AG13: 0.00054570198 | AH13: 3.1526276e-05 | AI13: 0.0017936223 | AJ13: 0.00015123457 | AK13: 7.878162e-05 | AL13: 0.00073079567 | AM13: 0.00044542384 | AN13: 0.00061383958 | AO13: 0.00010900888 | AP13: 3.0394723e-06 | AQ13: 3.4585739e-05 | AR13: 0.00014936445 | AS13: 1.1850119e-06 | AT13: 5.8420479e-07 | AU13: 7.0114737e-07 | AV13: 0 | AW13: 0 | AX13: 9.4542065e-09 | AY13: 6.7642398e-06 | AZ13: 2.5851402e-06 | BA13: 2.1076805e-08 | BB13: 0 | BC13: 5.275722e-08 | BD13: 1.0790378e-07 | BE13: 1.4864361e-09 | BF13: 4.5924346e-06 | BG13: 0 | BH13: 1.2011854e-05 | BI13: 3.0031778e-09 | BJ13: 8.6318035e-08 | BK13: 3.2002486e-07 | BL13: 0 | BM13: 7.3212959e-07 | BN13: 5.341172e-07 | BO13: 1.2381456e-09 | BP13: 1.1049086e-06 | BQ13: 4.9844552e-07 | BR13: 1.396628e-08 | BS13: 6.8606642e-07 | BT13: 0
B14: 1091 | C14: Abate e produtos de carne, inclusive os produtos do laticínio e da pesca | D14: 8 | E14: 0.00015050569 | F14: 0.015550448 | G14: 0.0011158411 | H14: 0.0004836337 | I14: 3.9205602e-05 | J14: 6.6926352e-05 | K14: 0.0001543414 | L14: 0.090330565 | M14: 0.00022353641 | N14: 0.0097202197 | O14: 0.0004195652 | P14: 0.00045914105 | Q14: 0.000424517 | R14: 0.00039818303 | S14: 0.034402186 | T14: 0.0016847187 | U14: 0.00083361364 | V14: 0.00014299712 | W14: 5.4843472e-05 | X14: 0.017041084 | Y14: 0.00035516599 | Z14: 0.0009180452 | AA14: 0.038833011 | AB14: 0.00075283746 | AC14: 0.00053216191 | AD14: 0.00049638525 | AE14: 0.00041373903 | AF14: 0.00024202121 | AG14: 0.0011259227 | AH14: 0.00025108435 | AI14: 0.00047641782 | AJ14: 0.00072784845 | AK14: 4.1195879e-05 | AL14: 2.6826168e-05 | AM14: 0.00015146243 | AN14: 0.0011205451 | AO14: 4.9243071e-05 | AP14: 1.2109418e-05 | AQ14: 2.3488815e-05 | AR14: 0.00011451088 | AS14: 9.2937874e-06 | AT14: 0.00061509078 | AU14: 1.51004e-06 | AV14: 3.1359261e-06 | AW14: 1.2362582e-06 | AX14: 1.71253e-05 | AY14: 0.020428657 | AZ14: 0.081075113 | BA14: 0.00065185712 | BB14: 0.00042770568 | BC14: 0.00052993427 | BD14: 8.7420429e-05 | BE14: 5.8564524e-06 | BF14: 8.5287195e-06 | BG14: 6.7269017e-05 | BH14: 8.8837475e-05 | BI14: 8.2577076e-05 | BJ14: 9.4415413e-06 | BK14: 6.7544816e-05 | BL14: 4.4198325e-05 | BM14: 0.0031541484 | BN14: 0.0040463715 | BO14: 0.002107412 | BP14: 0.0083371719 | BQ14: 0.0024081374 | BR14: 0.00018576338 | BS14: 0.001658994 | BT14: 0
B15: 1092 | C15: Fabricação e refino de açúcar | D15: 9 | E15: 9.4236421e-05 | F15: 0.00056891789 | G15: 4.7195302e-05 | H15: 6.1710733e-05 | I15: 0.0012833741 | J15: 0.00011164289 | K15: 0.00016651256 | L15: 0.0014023934 | M15: 0.020005754 | N15: 0.012882932 | O15: 0.012160667 | P15: 0.00011866626 | Q15: 0.00010604391 | R15: 0.00010756393 | S15: 0.00018110554 | T15: 0.00063611354 | U15: 0.00020902022 | V15: 2.6631709e-05 | W15: 0.020021854 | X15: 0.011713937 | Y15: 0.00067409236 | Z15: 0.0051199607 | AA15: 0.010323044 | AB15: 0.0041534823 | AC15: 0.00012409885 | AD15: 0.00012651083 | AE15: 0.00010427549 | AF15: 6.2398304e-05 | AG15: 0.00025281908 | AH15: 6.7246531e-05 | AI15: 0.00014517158 | AJ15: 0.00049470636 | AK15: 5.9219379e-05 | AL15: 1.5523585e-05 | AM15: 6.3926001e-05 | AN15: 9.7229778e-05 | AO15: 0.00031122375 | AP15: 1.3464169e-05 | AQ15: 0.00019675931 | AR15: 0.00029754784 | AS15: 0.00095479415 | AT15: 0.00033392082 | AU15: 0.00089586365 | AV15: 0.0001677581 | AW15: 0.00035010288 | AX15: 0.00020189442 | AY15: 0.00038362024 | AZ15: 0.0037763355 | BA15: 0.00033487079 | BB15: 0.00024442517 | BC15: 0.00021719059 | BD15: 0.00016167621 | BE15: 9.0824408e-05 | BF15: 1.9223623e-05 | BG15: 0.00028952999 | BH15: 0.00098254558 | BI15: 0.0002129337 | BJ15: 0.0011392293 | BK15: 0.00032094969 | BL15: 0.00081348616 | BM15: 0.00041875402 | BN15: 0.00028536379 | BO15: 0.00010177097 | BP15: 0.00048428673 | BQ15: 0.00020011043 | BR15: 0.00038113883 | BS15: 0.00051200146 | BT15: 0
B16: 1093 | C16: Outros produtos alimentares | D16: 10 | E16: 0.0042879275 | F16: 0.087675923 | G16: 0.03064632 | H16: 0.0080696509 | I16: 0.0008110189 | J16: 0.00049927876 | K16: 0.0011872652 | L16: 0.085996241 | M16: 0.0012671493 | N16: 0.095395418 | O16: 0.02879141 | P16: 0.0018085987 | Q16: 0.0021405049 | R16: 0.001639522 | S16: 0.0034341893 | T16: 0.0038077922 | U16: 0.0099659802 | V16: 0.0011126795 | W16: 0.006664422 | X16: 0.075472257 | Y16: 0.0035901872 | Z16: 0.011188111 | AA16: 0.021815386 | AB16: 0.0053624363 | AC16: 0.0028265961 | AD16: 0.0023854375 | AE16: 0.0018673043 | AF16: 0.0010605745 | AG16: 0.0021644282 | AH16: 0.0010209538 | AI16: 0.0019527546 | AJ16: 0.0028170428 | AK16: 0.00014646462 | AL16: 9.3026239e-05 | AM16: 0.00055927636 | AN16: 0.0023045655 | AO16: 0.00034474868 | AP16: 3.0476444e-05 | AQ16: 0.00036982635 | AR16: 0.00028545206 | AS16: 0.00073110161 | AT16: 0.0042439145 | AU16: 0.00031582173 | AV16: 7.3546259e-05 | AW16: 0.00057243053 | AX16: 0.00029453552 | AY16: 0.0083095019 | AZ16: 0.04760511 | BA16: 0.0026536478 | BB16: 0.0016936925 | BC16: 0.0022007348 | BD16: 0.00044533981 | BE16: 0.00020999628 | BF16: 4.7903656e-05 | BG16: 0.00052344071 | BH16: 0.00061680968 | BI16: 0.00073110683 | BJ16: 0.00048060076 | BK16: 0.00043039666 | BL16: 0.00045804239 | BM16: 0.0020611544 | BN16: 0.0033912887 | BO16: 0.0014140819 | BP16: 0.01070574 | BQ16: 0.00171377 | BR16: 0.0014538489 | BS16: 0.0052751523 | BT16: 0
B17: 1100 | C17: Fabricação de bebidas | D17: 11 | E17: 3.7711496e-06 | F17: 1.1719615e-05 | G17: 3.7290251e-06 | H17: 0.00040104365 | I17: 0.00010909759 | J17: 0.00014442613 | K17: 0.00023780465 | L17: 0.0018625382 | M17: 0.00020046947 | N17: 0.00070839755 | O17: 0.091291049 | P17: 0.00039668458 | Q17: 0.00035549436 | R17: 0.00035072488 | S17: 0.00061906834 | T17: 0.00042152194 | U17: 0.00064779304 | V17: 0.00012500443 | W17: 0.00015222175 | X17: 0.00022919791 | Y17: 0.00022248181 | Z17: 0.00053254958 | AA17: 0.00021685381 | AB17: 0.00063225431 | AC17: 0.0004536889 | AD17: 0.00043448295 | AE17: 0.00037913575 | AF17: 0.00020422717 | AG17: 0.00055681823 | AH17: 0.00023294253 | AI17: 0.00046575218 | AJ17: 0.0009247799 | AK17: 7.4170162e-05 | AL17: 5.0666048e-05 | AM17: 0.00019026953 | AN17: 0.00032626222 | AO17: 0.00034319942 | AP17: 1.4137116e-05 | AQ17: 3.4232491e-05 | AR17: 8.8959124e-05 | AS17: 4.4234828e-05 | AT17: 0.00022993503 | AU17: 1.6475412e-05 | AV17: 2.3486018e-05 | AW17: 0.00015509786 | AX17: 3.5704796e-05 | AY17: 0.017557685 | AZ17: 0.10038943 | BA17: 0.00057586836 | BB17: 0.00035951552 | BC17: 0.00047014862 | BD17: 8.5649644e-05 | BE17: 0.00012423968 | BF17: 5.7524426e-06 | BG17: 8.7153948e-05 | BH17: 4.2814369e-05 | BI17: 7.4632399e-05 | BJ17: 3.2306437e-05 | BK17: 8.4795985e-05 | BL17: 5.2946742e-05 | BM17: 0.00014412009 | BN17: 0.00021563281 | BO17: 0.00011496657 | BP17: 0.00045578309 | BQ17: 0.00044666025 | BR17: 0.00080382905 | BS17: 9.9783103e-05 | BT17: 0
B18: 1200 | C18: Fabricação de produtos do fumo | D18: 12 | E18: 1.2546644e-05 | F18: 3.4961585e-06 | G18: 1.2373893e-06 | H18: 4.8509703e-06 | I18: 1.6869525e-05 | J18: 2.4723218e-05 | K18: 2.7976807e-05 | L18: 5.4240353e-05 | M18: 1.419691e-05 | N18: 3.2094615e-05 | O18: 7.312246e-06 | P18: 0.035063506 | Q18: 2.4883173e-05 | R18: 2.5098785e-05 | S18: 4.5034224e-05 | T18: 2.7837853e-05 | U18: 5.2015184e-05 | V18: 1.0784093e-05 | W18: 3.1494311e-06 | X18: 1.4659671e-05 | Y18: 1.5765698e-05 | Z18: 2.9445592e-05 | AA18: 8.4380625e-06 | AB18: 4.5935171e-05 | AC18: 3.0830152e-05 | AD18: 3.0885817e-05 | AE18: 2.4553093e-05 | AF18: 1.6674518e-05 | AG18: 3.0925714e-05 | AH18: 1.6745609e-05 | AI18: 3.3960996e-05 | AJ18: 0.00010701817 | AK18: 7.4951462e-06 | AL18: 3.6959984e-06 | AM18: 1.3956225e-05 | AN18: 2.1041327e-05 | AO18: 6.0828959e-05 | AP18: 4.8350937e-07 | AQ18: 1.2856257e-06 | AR18: 3.5858171e-06 | AS18: 1.8054294e-06 | AT18: 1.3652238e-05 | AU18: 1.7856461e-07 | AV18: 4.4418474e-06 | AW18: 1.0520143e-07 | AX18: 1.7544784e-06 | AY18: 1.8698797e-06 | AZ18: 1.0371697e-06 | BA18: 4.4167941e-05 | BB18: 2.4837497e-05 | BC18: 3.3088735e-05 | BD18: 6.7375407e-06 | BE18: 5.8645383e-07 | BF18: 1.2783159e-07 | BG18: 4.7861436e-06 | BH18: 2.1827872e-05 | BI18: 4.8844699e-06 | BJ18: 2.2100553e-06 | BK18: 7.6961326e-06 | BL18: 2.800228e-06 | BM18: 2.0980177e-07 | BN18: 2.232071e-07 | BO18: 1.6394977e-06 | BP18: 6.3361756e-07 | BQ18: 4.9181708e-07 | BR18: 3.7169914e-06 | BS18: 1.1342936e-06 | BT18: 0
... B74: 9700 | C74: Serviços domésticos | D74: 68 | E74: 0 | F74: 0 | G74: 0 | H74: 0 | I74: 0 | J74: 0 | K74: 0 | L74: 0 | M74: 0 | N74: 0 | O74: 0 | P74: 0 | Q74: 0 | R74: 0 | S74: 0 | T74: 0 | U74: 0 | V74: 0 | W74: 0 | X74: 0 | Y74: 0 | Z74: 0 | AA74: 0 | AB74: 0 | AC74: 0 | AD74: 0 | AE74: 0 | AF74: 0 | AG74: 0 | AH74: 0 | AI74: 0 | AJ74: 0 | AK74: 0 | AL74: 0 | AM74: 0 | AN74: 0 | AO74: 0 | AP74: 0 | AQ74: 0 | AR74: 0 | AS74: 0 | AT74: 0 | AU74: 0 | AV74: 0 | AW74: 0 | AX74: 0 | AY74: 0 | AZ74: 0 | BA74: 0 | BB74: 0 | BC74: 0 | BD74: 0 | BE74: 0 | BF74: 0 | BG74: 0 | BH74: 0 | BI74: 0 | BJ74: 0 | BK74: 0 | BL74: 0 | BM74: 0 | BN74: 0 | BO74: 0 | BP74: 0 | BQ74: 0 | BR74: 0 | BS74: 0 | BT74: 0

Sheet B_2020
B2: Matriz B — inversa de Leontief (2020)
B3: B = (I−A)⁻¹, colada como VALOR (inversão externa NumPy; confira com MINVERSE). Base das fórmulas das questões.
B6: Código | C6: Atividades | E6: 1 | F6: 2 | G6: 3 | H6: 4 | I6: 5 | J6: 6 | K6: 7 | L6: 8 | M6: 9 | N6: 10 | O6: 11 | P6: 12 | Q6: 13 | R6: 14 | S6: 15 | T6: 16 | U6: 17 | V6: 18 | W6: 19 | X6: 20 | Y6: 21 | Z6: 22 | AA6: 23 | AB6: 24 | AC6: 25 | AD6: 26 | AE6: 27 | AF6: 28 | AG6: 29 | AH6: 30 | AI6: 31 | AJ6: 32 | AK6: 33 | AL6: 34 | AM6: 35 | AN6: 36 | AO6: 37 | AP6: 38 | AQ6: 39 | AR6: 40 | AS6: 41 | AT6: 42 | AU6: 43 | AV6: 44 | AW6: 45 | AX6: 46 | AY6: 47 | AZ6: 48 | BA6: 49 | BB6: 50 | BC6: 51 | BD6: 52 | BE6: 53 | BF6: 54 | BG6: 55 | BH6: 56 | BI6: 57 | BJ6: 58 | BK6: 59 | BL6: 60 | BM6: 61 | BN6: 62 | BO6: 63 | BP6: 64 | BQ6: 65 | BR6: 66 | BS6: 67 | BT6: 68
B7: 0191 | C7: Agricultura, inclusive o apoio à agricultura e a pós-colheita | D7: 1 | E7: 1.0290601 | F7: 0.082310178 | G7: 0.018368722 | H7: 0.011268356 | I7: 0.0064471141 | J7: 0.0052550459 | K7: 0.0088716628 | L7: 0.10239577 | M7: 0.49959884 | N7: 0.33554431 | O7: 0.058543913 | P7: 0.30579937 | Q7: 0.16273854 | R7: 0.056311416 | S7: 0.026249736 | T7: 0.015507314 | U7: 0.021481248 | V7: 0.0054918768 | W7: 0.048477871 | X7: 0.43057732 | Y7: 0.01252328 | Z7: 0.019595367 | AA7: 0.034202154 | AB7: 0.01979246 | AC7: 0.013739223 | AD7: 0.012817275 | AE7: 0.011107391 | AF7: 0.0090161114 | AG7: 0.011983959 | AH7: 0.0055762092 | AI7: 0.011174503 | AJ7: 0.013481757 | AK7: 0.0055076575 | AL7: 0.0068413762 | AM7: 0.0047888093 | AN7: 0.011473935 | AO7: 0.004281973 | AP7: 0.0022646011 | AQ7: 0.0034841298 | AR7: 0.0061621544 | AS7: 0.0041078142 | AT7: 0.019203366 | AU7: 0.013515101 | AV7: 0.0057499135 | AW7: 0.010055383 | AX7: 0.0034763381 | AY7: 0.023296058 | AZ7: 0.054561058 | BA7: 0.011276158 | BB7: 0.0090286688 | BC7: 0.0095347619 | BD7: 0.0026448991 | BE7: 0.0014683486 | BF7: 0.00037785696 | BG7: 0.0029630335 | BH7: 0.0040447563 | BI7: 0.0051646239 | BJ7: 0.0040446007 | BK7: 0.0036658526 | BL7: 0.0032569054 | BM7: 0.0043654609 | BN7: 0.0038897329 | BO7: 0.0028456988 | BP7: 0.010129411 | BQ7: 0.0045753481 | BR7: 0.0032680341 | BS7: 0.011511374 | BT7: 0
B8: 0192 | C8: Pecuária, inclusive o apoio à pecuária | D8: 2 | E8: 0.0034732763 | F8: 1.0542163 | G8: 0.0079525576 | H8: 0.0011686014 | I8: 0.00068944227 | J8: 0.00062727145 | K8: 0.00096696063 | L8: 0.34538069 | M8: 0.0049478481 | N8: 0.023533872 | O8: 0.0027153405 | P8: 0.014845114 | Q8: 0.010006317 | R8: 0.008051497 | S8: 0.014831286 | T8: 0.0072869966 | U8: 0.005539634 | V8: 0.00084675041 | W8: 0.0015789822 | X8: 0.012959398 | Y8: 0.0013597981 | Z8: 0.0018317818 | AA8: 0.015437405 | AB8: 0.0017225793 | AC8: 0.0018655557 | AD8: 0.0020470987 | AE8: 0.0017355028 | AF8: 0.0017060805 | AG8: 0.0016874772 | AH8: 0.00062529682 | AI8: 0.0012609823 | AJ8: 0.0014586109 | AK8: 0.00075864954 | AL8: 0.00080605178 | AM8: 0.00060048377 | AN8: 0.001939987 | AO8: 0.00052938737 | AP8: 0.00028544296 | AQ8: 0.00046569132 | AR8: 0.0022503248 | AS8: 0.00043644438 | AT8: 0.0012428355 | AU8: 0.00060368609 | AV8: 0.00037812423 | AW8: 0.0010502917 | AX8: 0.00054650183 | AY8: 0.023057364 | AZ8: 0.038645486 | BA8: 0.0013113761 | BB8: 0.0016374335 | BC8: 0.0015416078 | BD8: 0.00040864288 | BE8: 0.00038563218 | BF8: 0.00012420114 | BG8: 0.00061672945 | BH8: 0.00067798735 | BI8: 0.00096115351 | BJ8: 0.0003943411 | BK8: 0.00073068971 | BL8: 0.00028684687 | BM8: 0.0021660904 | BN8: 0.002149311 | BO8: 0.0012889473 | BP8: 0.0050285175 | BQ8: 0.002146925 | BR8: 0.00063198019 | BS8: 0.0042860231 | BT8: 0
B9: 0280 | C9: Produção florestal; pesca e aquicultura | D9: 3 | E9: 0.0040943514 | F9: 0.010683339 | G9: 1.062448 | H9: 0.00062543019 | I9: 0.00089429409 | J9: 0.00050231304 | K9: 0.00070765038 | L9: 0.012853646 | M9: 0.002327702 | N9: 0.0038574872 | O9: 0.001570981 | P9: 0.0044836011 | Q9: 0.0027077296 | R9: 0.0015581588 | S9: 0.0022923495 | T9: 0.0650126 | U9: 0.042822479 | V9: 0.0030235644 | W9: 0.00067088062 | X9: 0.0024889746 | Y9: 0.00200803 | Z9: 0.0011382007 | AA9: 0.0027385761 | AB9: 0.0013477176 | AC9: 0.0072467723 | AD9: 0.0027652248 | AE9: 0.0080175151 | AF9: 0.00080769017 | AG9: 0.0031010025 | AH9: 0.00081317901 | AI9: 0.0015028058 | AJ9: 0.0017538555 | AK9: 0.0015315249 | AL9: 0.001837901 | AM9: 0.00093612198 | AN9: 0.0064428143 | AO9: 0.00077169515 | AP9: 0.00032998727 | AQ9: 0.00049497733 | AR9: 0.003313998 | AS9: 0.00061520751 | AT9: 0.0010229527 | AU9: 0.00051385245 | AV9: 0.00037579348 | AW9: 0.00049068836 | AX9: 0.00041814272 | AY9: 0.0026861997 | AZ9: 0.0040759878 | BA9: 0.0026909643 | BB9: 0.00096250905 | BC9: 0.00071795726 | BD9: 0.00041420175 | BE9: 0.00025543433 | BF9: 0.0001226738 | BG9: 0.00054208482 | BH9: 0.00058003884 | BI9: 0.00077236417 | BJ9: 0.00067993973 | BK9: 0.00066162206 | BL9: 0.00018769201 | BM9: 0.00043884158 | BN9: 0.00049473755 | BO9: 0.00048615377 | BP9: 0.0010353991 | BQ9: 0.00064774129 | BR9: 0.00039904323 | BS9: 0.00087930171 | BT9: 0
B10: 0580 | C10: Extração de carvão mineral e de minerais não-metálicos | D10: 4 | E10: 0.0038037746 | F10: 0.005021771 | G10: 0.0010695051 | H10: 1.0135053 | I10: 0.0047695505 | J10: 0.0010574976 | K10: 0.0018456546 | L10: 0.0030383287 | M10: 0.0025812063 | N10: 0.0033191674 | O10: 0.0031116901 | P10: 0.001629816 | Q10: 0.0033095272 | R10: 0.0012300667 | S10: 0.001854668 | T10: 0.00162793 | U10: 0.0026348997 | V10: 0.001034711 | W10: 0.0021829959 | X10: 0.0049664763 | Y10: 0.022460267 | Z10: 0.004847729 | AA10: 0.0036743888 | AB10: 0.0013052021 | AC10: 0.0052591891 | AD10: 0.062316279 | AE10: 0.012324522 | AF10: 0.0081959687 | AG10: 0.0039628067 | AH10: 0.00056421069 | AI10: 0.0038527121 | AJ10: 0.0022047127 | AK10: 0.0027894082 | AL10: 0.003105287 | AM10: 0.0015738861 | AN10: 0.0026696756 | AO10: 0.001378466 | AP10: 0.0017547596 | AQ10: 0.007215606 | AR10: 0.018134608 | AS10: 0.00088308593 | AT10: 0.00069146554 | AU10: 0.0009166521 | AV10: 0.00048648601 | AW10: 0.00066260879 | AX10: 0.00062073851 | AY10: 0.0015779241 | AZ10: 0.0013387851 | BA10: 0.00073252204 | BB10: 0.00063272527 | BC10: 0.00093730238 | BD10: 0.00033089144 | BE10: 0.00018337028 | BF10: 0.00084974691 | BG10: 0.0003195867 | BH10: 0.00049917298 | BI10: 0.00040252748 | BJ10: 0.00047408859 | BK10: 0.00071388295 | BL10: 0.00018239701 | BM10: 0.00065386257 | BN10: 0.00030438009 | BO10: 0.00036861847 | BP10: 0.00088612993 | BQ10: 0.00043663043 | BR10: 0.00061590597 | BS10: 0.00078933674 | BT10: 0
B11: 0680 | C11: Extração de petróleo e gás, inclusive as atividades de apoio | D11: 5 | E11: 0.01830561 | F11: 0.017344515 | G11: 0.010653425 | H11: 0.029074551 | I11: 1.0438635 | J11: 0.026579358 | K11: 0.037544798 | L11: 0.026022223 | M11: 0.022680766 | N11: 0.024209465 | O11: 0.016734598 | P11: 0.013258621 | Q11: 0.018975425 | R11: 0.010749812 | S11: 0.015881828 | T11: 0.018031143 | U11: 0.030478913 | V11: 0.0081569631 | W11: 0.32989449 | X11: 0.018739766 | Y11: 0.044614461 | Z11: 0.020533605 | AA11: 0.017587556 | AB11: 0.014791751 | AC11: 0.023685616 | AD11: 0.032502205 | AE11: 0.028648366 | AF11: 0.029599919 | AG11: 0.020184668 | AH11: 0.0067824537 | AI11: 0.018265663 | AJ11: 0.015129521 | AK11: 0.012567124 | AL11: 0.013142442 | AM11: 0.0081308304 | AN11: 0.012814619 | AO11: 0.0072406003 | AP11: 0.04611316 | AQ11: 0.02357057 | AR11: 0.014538615 | AS11: 0.005988935 | AT11: 0.013944832 | AU11: 0.072923316 | AV11: 0.029251462 | AW11: 0.050141391 | AX11: 0.012647697 | AY11: 0.0083748906 | AZ11: 0.010001246 | BA11: 0.011116317 | BB11: 0.0079109006 | BC11: 0.0087979843 | BD11: 0.0030254584 | BE11: 0.001938099 | BF11: 0.00059250543 | BG11: 0.0036633269 | BH11: 0.0062575192 | BI11: 0.0049145791 | BJ11: 0.0066782593 | BK11: 0.0048623952 | BL11: 0.0048492882 | BM11: 0.0058897192 | BN11: 0.0019226055 | BO11: 0.0041558061 | BP11: 0.0039996722 | BQ11: 0.0028200729 | BR11: 0.0053104289 | BS11: 0.0079139319 | BT11: 0
B12: 0791 | C12: Extração de minério de ferro, inclusive beneficiamentos e a aglomeração | D12: 6 | E12: 0.0010742968 | F12: 0.0018294365 | G12: 0.00078163201 | H12: 0.0034624649 | I12: 0.020083464 | J12: 1.028374 | K12: 0.010612695 | L12: 0.0033300427 | M12: 0.0015398912 | N12: 0.0024667248 | O12: 0.0057852312 | P12: 0.0012365436 | Q12: 0.0016241957 | R12: 0.0012488152 | S12: 0.0016983612 | T12: 0.003096029 | U12: 0.0031857072 | V12: 0.0018773807 | W12: 0.0067639673 | X12: 0.0013694785 | Y12: 0.002216244 | Z12: 0.0024482022 | AA12: 0.0030097738 | AB12: 0.0016136871 | AC12: 0.0043371536 | AD12: 0.0082982181 | AE12: 0.26774132 | AF12: 0.0095583836 | AG12: 0.058811862 | AH12: 0.0020458894 | AI12: 0.016552082 | AJ12: 0.02579542 | AK12: 0.019398384 | AL12: 0.029121304 | AM12: 0.0094759807 | AN12: 0.0078543456 | AO12: 0.011762525 | AP12: 0.0025108825 | AQ12: 0.0029354472 | AR12: 0.01244381 | AS12: 0.0040900514 | AT12: 0.0015674952 | AU12: 0.0033417132 | AV12: 0.0020384505 | AW12: 0.0017085979 | AX12: 0.0012785028 | AY12: 0.0015007875 | AZ12: 0.0019415972 | BA12: 0.001562162 | BB12: 0.0011384444 | BC12: 0.0015196579 | BD12: 0.0006363908 | BE12: 0.00028027923 | BF12: 0.00020887828 | BG12: 0.00056381317 | BH12: 0.00099882847 | BI12: 0.00072961235 | BJ12: 0.0023058038 | BK12: 0.00096952314 | BL12: 0.00055821361 | BM12: 0.00076457434 | BN12: 0.0003275317 | BO12: 0.00053988665 | BP12: 0.0010213121 | BQ12: 0.00061681008 | BR12: 0.0011037811 | BS12: 0.00096760912 | BT12: 0
B13: 0792 | C13: Extração de minerais metálicos não-ferrosos, inclusive beneficiamentos | D13: 7 | E13: 0.00040189565 | F13: 0.00042811984 | G13: 0.00017901127 | H13: 0.00069458838 | I13: 0.002077488 | J13: 0.0008007035 | K13: 1.0748199 | L13: 0.00097927939 | M13: 0.00047460773 | N13: 0.0009305941 | O13: 0.0011229712 | P13: 0.00039942075 | Q13: 0.00054049567 | R13: 0.00042734132 | S13: 0.00053706395 | T13: 0.00075268819 | U13: 0.0014163504 | V13: 0.0028183147 | W13: 0.00078878454 | X13: 0.00043761067 | Y13: 0.0012920297 | Z13: 0.0011668488 | AA13: 0.00083446868 | AB13: 0.00050811135 | AC13: 0.0009665519 | AD13: 0.0018563004 | AE13: 0.016708361 | AF13: 0.12874562 | AG13: 0.0086306871 | AH13: 0.0010236964 | AI13: 0.017597606 | AJ13: 0.0046873076 | AK13: 0.0043490216 | AL13: 0.0096929975 | AM13: 0.0050075383 | AN13: 0.0055693984 | AO13: 0.004233023 | AP13: 0.0007627433 | AQ13: 0.00082287669 | AR13: 0.0024778579 | AS13: 0.0017059368 | AT13: 0.00041342637 | AU13: 0.00086572184 | AV13: 0.0005470634 | AW13: 0.00033822073 | AX13: 0.00037303985 | AY13: 0.00043423732 | AZ13: 0.00046452223 | BA13: 0.00062499475 | BB13: 0.00038922656 | BC13: 0.00045943287 | BD13: 0.0002061369 | BE13: 0.00010003798 | BF13: 7.577186e-05 | BG13: 0.00024271485 | BH13: 0.00027463362 | BI13: 0.0003110749 | BJ13: 0.00046368932 | BK13: 0.00030442553 | BL13: 0.00015254745 | BM13: 0.00017119949 | BN13: 9.7723307e-05 | BO13: 0.00020222575 | BP13: 0.00031160431 | BQ13: 0.00032049224 | BR13: 0.00048625717 | BS13: 0.00039414068 | BT13: 0
B14: 1091 | C14: Abate e produtos de carne, inclusive os produtos do laticínio e da pesca | D14: 8 | E14: 0.00087781285 | F14: 0.019680511 | G14: 0.0020428113 | H14: 0.0015509775 | I14: 0.00082766376 | J14: 0.00064470082 | K14: 0.0010902344 | L14: 1.1081638 | M14: 0.0013072612 | N14: 0.013570526 | O14: 0.0019004336 | P14: 0.0017973335 | Q14: 0.0017814989 | R14: 0.0015400053 | S14: 0.043150622 | T14: 0.0033904 | U14: 0.0028082713 | V14: 0.0009521089 | W14: 0.0020857741 | X14: 0.020902558 | Y14: 0.0016328052 | Z14: 0.0029254533 | AA14: 0.045676217 | AB14: 0.0026585561 | AC14: 0.0019949444 | AD14: 0.0018104279 | AE14: 0.0015801084 | AF14: 0.0012618098 | AG14: 0.0027586599 | AH14: 0.00095338525 | AI14: 0.0017711248 | AJ14: 0.0022902021 | AK14: 0.00098363084 | AL14: 0.00076492585 | AM14: 0.00079331541 | AN14: 0.002372216 | AO14: 0.00078346657 | AP14: 0.00043378303 | AQ14: 0.0004238371 | AR14: 0.00089522461 | AS14: 0.00056190912 | AT14: 0.0014770423 | AU14: 0.0007960911 | AV14: 0.00049580443 | AW14: 0.0018587388 | AX14: 0.00052880815 | AY14: 0.02426511 | AZ14: 0.091087243 | BA14: 0.0018843452 | BB14: 0.0030731758 | BC14: 0.0017978112 | BD14: 0.00057162878 | BE14: 0.0006189815 | BF14: 8.9480882e-05 | BG14: 0.0010882739 | BH14: 0.00064055926 | BI14: 0.0015848739 | BJ14: 0.00051245668 | BK14: 0.0011292444 | BL14: 0.00040673041 | BM14: 0.004739395 | BN14: 0.0051058922 | BO14: 0.0029312075 | BP14: 0.01195905 | BQ14: 0.004639826 | BR14: 0.00095778156 | BS14: 0.0086177876 | BT14: 0
B15: 1092 | C15: Fabricação e refino de açúcar | D15: 9 | E15: 0.0023688857 | F15: 0.0038575587 | G15: 0.0015781392 | H15: 0.0035473639 | I15: 0.0028861983 | J15: 0.0022848963 | K15: 0.0036567607 | L15: 0.0066846089 | M15: 1.0231372 | N15: 0.017423192 | O15: 0.015945024 | P15: 0.0018930476 | Q15: 0.0022104643 | R15: 0.0014721948 | S15: 0.0023616393 | T15: 0.0029036988 | U15: 0.0035007154 | V15: 0.0012654227 | W15: 0.029702157 | X15: 0.015462648 | Y15: 0.0047271461 | Z15: 0.0085900521 | AA15: 0.013755301 | AB15: 0.0066172935 | AC15: 0.0029236692 | AD15: 0.0032159771 | AE15: 0.0028473489 | AF15: 0.0026464888 | AG15: 0.0024326863 | AH15: 0.00098211192 | AI15: 0.0022229408 | AJ15: 0.0025204737 | AK15: 0.0014603146 | AL15: 0.0013239337 | AM15: 0.0010362574 | AN15: 0.0017286207 | AO15: 0.0012725528 | AP15: 0.00090612825 | AQ15: 0.0011588254 | AR15: 0.0017333967 | AS15: 0.0017061937 | AT15: 0.0019089689 | AU15: 0.0078141884 | AV15: 0.0030199978 | AW15: 0.0051790888 | AX15: 0.0015348638 | AY15: 0.0015919622 | AZ15: 0.0073530408 | BA15: 0.0018898111 | BB15: 0.0015249347 | BC15: 0.0013739313 | BD15: 0.00060372926 | BE15: 0.00039439363 | BF15: 0.00010453602 | BG15: 0.00080649313 | BH15: 0.0017084909 | BI15: 0.0010604053 | BJ15: 0.0019826021 | BK15: 0.00092195325 | BL15: 0.0013887431 | BM15: 0.00089947405 | BN15: 0.0006211698 | BO15: 0.00059844538 | BP15: 0.00144976 | BQ15: 0.00087341369 | BR15: 0.00099909564 | BS15: 0.001886104 | BT15: 0
B16: 1093 | C16: Outros produtos alimentares | D16: 10 | E16: 0.0087191786 | F16: 0.10743137 | G16: 0.038096821 | H16: 0.01359028 | I16: 0.0036510168 | J16: 0.0030361488 | K16: 0.0054357594 | L16: 0.14661528 | M16: 0.0085340006 | N16: 1.1164785 | O16: 0.039338889 | P16: 0.0095749995 | Q16: 0.0092476301 | R16: 0.0070933612 | S16: 0.01532449 | T16: 0.012752789 | U16: 0.021800156 | V16: 0.0050437304 | W16: 0.018208812 | X16: 0.093223872 | Y16: 0.0097371716 | Z16: 0.020168193 | AA16: 0.037362896 | AB16: 0.012605611 | AC16: 0.010114289 | AD16: 0.0091867349 | AE16: 0.0073816878 | AF16: 0.0054725579 | AG16: 0.0083945523 | AH16: 0.0039082096 | AI16: 0.0076442104 | AJ16: 0.0092933146 | AK16: 0.0032929071 | AL16: 0.0031419387 | AM16: 0.0031044288 | AN16: 0.007436599 | AO16: 0.0030803895 | AP16: 0.0013176051 | AQ16: 0.001996907 | AR16: 0.0037702494 | AS16: 0.0024888111 | AT16: 0.0074807547 | AU16: 0.0054195132 | AV16: 0.0025430215 | AW16: 0.0052414853 | AX16: 0.0019690111 | AY16: 0.016470902 | AZ16: 0.070999152 | BA16: 0.0081525998 | BB16: 0.0068448631 | BC16: 0.0066308812 | BD16: 0.0018499495 | BE16: 0.0012335134 | BF16: 0.0003004289 | BG16: 0.0023129066 | BH16: 0.0022040815 | BI16: 0.0041545359 | BJ16: 0.0021076878 | BK16: 0.002393858 | BL16: 0.0015655268 | BM16: 0.0042524844 | BN16: 0.0052227316 | BO16: 0.0030307157 | BP16: 0.016172643 | BQ16: 0.0048046327 | BR16: 0.0031581209 | BS16: 0.012385204 | BT16: 0
B17: 1100 | C17: Fabricação de bebidas | D17: 11 | E17: 0.00026562968 | F17: 0.00037185635 | G17: 0.00014642971 | H17: 0.00087977042 | I17: 0.0006490805 | J17: 0.00049011844 | K17: 0.00081402685 | L17: 0.0030769085 | M17: 0.00061401523 | N17: 0.0014901938 | O17: 1.1010143 | P17: 0.00095823442 | Q17: 0.00093607635 | R17: 0.00089287816 | S17: 0.0014340691 | T17: 0.0010268619 | U17: 0.0015508668 | V17: 0.0006142919 | W17: 0.00059750231 | X17: 0.00073318565 | Y17: 0.0007773351 | Z17: 0.0014098747 | AA17: 0.00085918038 | AB17: 0.0017773656 | AC17: 0.0011663493 | AD17: 0.0011297198 | AE17: 0.0010751049 | AF17: 0.00083361763 | AG17: 0.0013714832 | AH17: 0.00066363479 | AI17: 0.0012140929 | AJ17: 0.0019352793 | AK17: 0.00078157596 | AL17: 0.00050992907 | AM17: 0.00059132345 | AN17: 0.00087514844 | AO17: 0.00090653378 | AP17: 0.00033868749 | AQ17: 0.00026744495 | AR17: 0.00051202414 | AS17: 0.0004124288 | AT17: 0.00069578903 | AU17: 0.0003343024 | AV17: 0.00032211073 | AW17: 0.0019772192 | AX17: 0.00037599617 | AY17: 0.020538704 | AZ17: 0.11096994 | BA17: 0.001267581 | BB17: 0.0029298292 | BC17: 0.0013058774 | BD17: 0.00043844709 | BE17: 0.00076280893 | BF17: 7.3327089e-05 | BG17: 0.0010351565 | BH17: 0.00033745524 | BI17: 0.001330148 | BJ17: 0.0003092142 | BK17: 0.00080958749 | BL17: 0.00024278689 | BM17: 0.0015124023 | BN17: 0.00084715452 | BO17: 0.00062092296 | BP17: 0.0034041085 | BQ17: 0.0021110055 | BR17: 0.0013631941 | BS17: 0.0075168177 | BT17: 0
B18: 1200 | C18: Fabricação de produtos do fumo | D18: 12 | E18: 2.3024995e-05 | F18: 1.7618721e-05 | G18: 6.0099877e-06 | H18: 2.0695945e-05 | I18: 3.2694973e-05 | J18: 3.9121078e-05 | K18: 5.156543e-05 | L18: 9.1791562e-05 | M18: 3.3486523e-05 | N18: 6.0239196e-05 | O18: 2.6250446e-05 | P18: 1.0363571 | Q18: 4.820476e-05 | R18: 4.6679827e-05 | S18: 7.465068e-05 | T18: 5.1671823e-05 | U18: 8.8820498e-05 | V18: 3.0956526e-05 | W18: 2.0796085e-05 | X18: 3.6646976e-05 | Y18: 3.2010841e-05 | Z18: 5.3379564e-05 | AA18: 3.0402424e-05 | AB18: 6.7683061e-05 | AC18: 5.706692e-05 | AD18: 5.6255744e-05 | AE18: 5.6656669e-05 | AF18: 4.0484531e-05 | AG18: 6.1448398e-05 | AH18: 3.0990311e-05 | AI18: 6.3797892e-05 | AJ18: 0.00015102028 | AK18: 2.6141702e-05 | AL18: 2.26244e-05 | AM18: 2.986574e-05 | AN18: 4.2459083e-05 | AO18: 8.9824307e-05 | AP18: 7.2849042e-06 | AQ18: 9.2332506e-06 | AR18: 2.1217299e-05 | AS18: 9.4450478e-06 | AT18: 2.2887809e-05 | AU18: 9.5662075e-06 | AV18: 1.6758575e-05 | AW18: 9.5040651e-06 | AX18: 9.2698563e-06 | AY18: 1.0751435e-05 | AZ18: 1.7509983e-05 | BA18: 6.6017132e-05 | BB18: 4.2074025e-05 | BC18: 5.1504173e-05 | BD18: 1.3276009e-05 | BE18: 4.0597575e-06 | BF18: 1.154446e-06 | BG18: 1.047464e-05 | BH18: 2.8463325e-05 | BI18: 2.2412188e-05 | BJ18: 8.850982e-06 | BK18: 1.4301257e-05 | BL18: 6.5588507e-06 | BM18: 3.8011382e-06 | BN18: 3.1562496e-06 | BO18: 6.2022573e-06 | BP18: 8.3422296e-06 | BQ18: 6.9596222e-06 | BR18: 1.0323086e-05 | BS18: 8.8380605e-06 | BT18: 0
... B74: 9700 | C74: Serviços domésticos | D74: 68 | E74: 0 | F74: 0 | G74: 0 | H74: 0 | I74: 0 | J74: 0 | K74: 0 | L74: 0 | M74: 0 | N74: 0 | O74: 0 | P74: 0 | Q74: 0 | R74: 0 | S74: 0 | T74: 0 | U74: 0 | V74: 0 | W74: 0 | X74: 0 | Y74: 0 | Z74: 0 | AA74: 0 | AB74: 0 | AC74: 0 | AD74: 0 | AE74: 0 | AF74: 0 | AG74: 0 | AH74: 0 | AI74: 0 | AJ74: 0 | AK74: 0 | AL74: 0 | AM74: 0 | AN74: 0 | AO74: 0 | AP74: 0 | AQ74: 0 | AR74: 0 | AS74: 0 | AT74: 0 | AU74: 0 | AV74: 0 | AW74: 0 | AX74: 0 | AY74: 0 | AZ74: 0 | BA74: 0 | BB74: 0 | BC74: 0 | BD74: 0 | BE74: 0 | BF74: 0 | BG74: 0 | BH74: 0 | BI74: 0 | BJ74: 0 | BK74: 0 | BL74: 0 | BM74: 0 | BN74: 0 | BO74: 0 | BP74: 0 | BQ74: 0 | BR74: 0 | BS74: 0 | BT74: 1

Sheet G_2020
B2: Matriz G — inversa de Ghosh (2020)
B3: G = (I−x̂⁻¹Z)⁻¹, colada como VALOR; usada na ligação para frente (Q4).
B6: Código | C6: Atividades | E6: 1 | F6: 2 | G6: 3 | H6: 4 | I6: 5 | J6: 6 | K6: 7 | L6: 8 | M6: 9 | N6: 10 | O6: 11 | P6: 12 | Q6: 13 | R6: 14 | S6: 15 | T6: 16 | U6: 17 | V6: 18 | W6: 19 | X6: 20 | Y6: 21 | Z6: 22 | AA6: 23 | AB6: 24 | AC6: 25 | AD6: 26 | AE6: 27 | AF6: 28 | AG6: 29 | AH6: 30 | AI6: 31 | AJ6: 32 | AK6: 33 | AL6: 34 | AM6: 35 | AN6: 36 | AO6: 37 | AP6: 38 | AQ6: 39 | AR6: 40 | AS6: 41 | AT6: 42 | AU6: 43 | AV6: 44 | AW6: 45 | AX6: 46 | AY6: 47 | AZ6: 48 | BA6: 49 | BB6: 50 | BC6: 51 | BD6: 52 | BE6: 53 | BF6: 54 | BG6: 55 | BH6: 56 | BI6: 57 | BJ6: 58 | BK6: 59 | BL6: 60 | BM6: 61 | BN6: 62 | BO6: 63 | BP6: 64 | BQ6: 65 | BR6: 66 | BS6: 67 | BT6: 68
B7: 0191 | C7: Agricultura, inclusive o apoio à agricultura e a pós-colheita | D7: 1 | E7: 1.0290601 | F7: 0.030602692 | G7: 0.0014225977 | H7: 0.00047678729 | I7: 0.0028028526 | J7: 0.0014973455 | K7: 0.00038180883 | L7: 0.074260602 | M7: 0.064872957 | N7: 0.24053859 | O7: 0.010368947 | P7: 0.0096186231 | Q7: 0.016792015 | R7: 0.0065601122 | S7: 0.0017608918 | T7: 0.0011125935 | U7: 0.0047163233 | V7: 0.00019034489 | W7: 0.039295286 | X7: 0.057147927 | Y7: 0.0048033651 | Z7: 0.0042518064 | AA7: 0.0037659388 | AB7: 0.0031444478 | AC7: 0.0034106909 | AD7: 0.0023713336 | AE7: 0.003123029 | AF7: 0.0014082774 | AG7: 0.0027420149 | AH7: 0.0011844063 | AI7: 0.0020283699 | AJ7: 0.0038353082 | AK7: 0.0016499992 | AL7: 0.0012537795 | AM7: 0.00036466804 | AN7: 0.001840345 | AO7: 0.00069168252 | AP7: 0.0014760715 | AQ7: 0.000614512 | AR7: 0.006873821 | AS7: 0.0013133197 | AT7: 0.042982181 | AU7: 0.010362003 | AV7: 0.00031432069 | AW7: 0.00047357194 | AX7: 0.00096259049 | AY7: 0.00087446077 | AZ7: 0.024051752 | BA7: 0.0003383749 | BB7: 0.0006383688 | BC7: 0.0029719607 | BD7: 0.0010076914 | BE7: 0.0018743294 | BF7: 0.00048971243 | BG7: 0.0013288476 | BH7: 0.0005390386 | BI7: 0.0010980094 | BJ7: 0.00045935407 | BK7: 0.0018502345 | BL7: 0.000272819 | BM7: 0.0072206481 | BN7: 0.0027190026 | BO7: 0.00072682351 | BP7: 0.0045214476 | BQ7: 0.0026453654 | BR7: 0.00023391012 | BS7: 0.0036104975 | BT7: 0
